Workbook

Sheet Run Comparison
A1: Run-by-Run Field Comparison — RAG & Zero Shot
A2: Compares Max Points, Estimated Level, Estimated Points, % Achieved and Justification across the 5 runs of each arm, keyed by Category + Credit ID + Credit Name. 'Consistent?' = Yes when all 5 runs match.
A4: RAG — Run-by-Run Comparison (5 runs, 47 credits)
A5: Max Points
A6: Category | B6: Credit ID | C6: Credit Name | D6: Run 1 | E6: Run 2 | F6: Run 3 | G6: Run 4 | H6: Run 5 | I6: Consistent?
A7: ='RAG Run 1'!D2 -> Climate And Resilience | B7: ='RAG Run 1'!E2 -> CR2.1 | C7: ='RAG Run 1'!F2 -> Avoid Unsuitable Development | D7: =IF('RAG Run 1'!G2="","",'RAG Run 1'!G2) -> 14 | E7: =IF('RAG Run 2'!G2="","",'RAG Run 2'!G2) -> 14 | F7: =IF('RAG Run 3'!G2="","",'RAG Run 3'!G2) -> 14 | G7: =IF('RAG Run 4'!G2="","",'RAG Run 4'!G2) -> 14 | H7: =IF('RAG Run 5'!G2="","",'RAG Run 5'!G2) -> 14 | I7: =IF(AND(D7=E7,E7=F7,F7=G7,G7=H7),"Yes","No") -> Yes
A8: ='RAG Run 1'!D3 -> Climate And Resilience | B8: ='RAG Run 1'!E3 -> CR2.2 | C8: ='RAG Run 1'!F3 -> Assess Climate Change Vulnerability | D8: =IF('RAG Run 1'!G3="","",'RAG Run 1'!G3) -> 20 | E8: =IF('RAG Run 2'!G3="","",'RAG Run 2'!G3) -> 20 | F8: =IF('RAG Run 3'!G3="","",'RAG Run 3'!G3) -> 20 | G8: =IF('RAG Run 4'!G3="","",'RAG Run 4'!G3) -> 20 | H8: =IF('RAG Run 5'!G3="","",'RAG Run 5'!G3) -> 20 | I8: =IF(AND(D8=E8,E8=F8,F8=G8,G8=H8),"Yes","No") -> Yes
A9: ='RAG Run 1'!D4 -> Climate And Resilience | B9: ='RAG Run 1'!E4 -> CR2.3 | C9: ='RAG Run 1'!F4 -> Evaluate Risk and Resilience | D9: =IF('RAG Run 1'!G4="","",'RAG Run 1'!G4) -> 26 | E9: =IF('RAG Run 2'!G4="","",'RAG Run 2'!G4) -> 26 | F9: =IF('RAG Run 3'!G4="","",'RAG Run 3'!G4) -> 26 | G9: =IF('RAG Run 4'!G4="","",'RAG Run 4'!G4) -> 26 | H9: =IF('RAG Run 5'!G4="","",'RAG Run 5'!G4) -> 26 | I9: =IF(AND(D9=E9,E9=F9,F9=G9,G9=H9),"Yes","No") -> Yes
A10: ='RAG Run 1'!D5 -> Climate And Resilience | B10: ='RAG Run 1'!E5 -> CR2.4 | C10: ='RAG Run 1'!F5 -> Establish Resilience Goals and Strategies | D10: =IF('RAG Run 1'!G5="","",'RAG Run 1'!G5) -> 20 | E10: =IF('RAG Run 2'!G5="","",'RAG Run 2'!G5) -> 20 | F10: =IF('RAG Run 3'!G5="","",'RAG Run 3'!G5) -> 20 | G10: =IF('RAG Run 4'!G5="","",'RAG Run 4'!G5) -> 20 | H10: =IF('RAG Run 5'!G5="","",'RAG Run 5'!G5) -> 20 | I10: =IF(AND(D10=E10,E10=F10,F10=G10,G10=H10),"Yes","No") -> Yes
A11: ='RAG Run 1'!D6 -> Climate And Resilience | B11: ='RAG Run 1'!E6 -> CR2.5 | C11: ='RAG Run 1'!F6 -> Maximize Resilience | D11: =IF('RAG Run 1'!G6="","",'RAG Run 1'!G6) -> 26 | E11: =IF('RAG Run 2'!G6="","",'RAG Run 2'!G6) -> 26 | F11: =IF('RAG Run 3'!G6="","",'RAG Run 3'!G6) -> 26 | G11: =IF('RAG Run 4'!G6="","",'RAG Run 4'!G6) -> 26 | H11: =IF('RAG Run 5'!G6="","",'RAG Run 5'!G6) -> 26 | I11: =IF(AND(D11=E11,E11=F11,F11=G11,G11=H11),"Yes","No") -> Yes
A12: ='RAG Run 1'!D7 -> Climate And Resilience | B12: ='RAG Run 1'!E7 -> CR2.6 | C12: ='RAG Run 1'!F7 -> Improve Infrastructure Integration | D12: =IF('RAG Run 1'!G7="","",'RAG Run 1'!G7) -> 18 | E12: =IF('RAG Run 2'!G7="","",'RAG Run 2'!G7) -> 18 | F12: =IF('RAG Run 3'!G7="","",'RAG Run 3'!G7) -> 18 | G12: =IF('RAG Run 4'!G7="","",'RAG Run 4'!G7) -> 18 | H12: =IF('RAG Run 5'!G7="","",'RAG Run 5'!G7) -> 18 | I12: =IF(AND(D12=E12,E12=F12,F12=G12,G12=H12),"Yes","No") -> Yes
A13: ='RAG Run 1'!D8 -> Leadership | B13: ='RAG Run 1'!E8 -> LD1.1 | C13: ='RAG Run 1'!F8 -> Provide Effective Leadership and Commitment | D13: =IF('RAG Run 1'!G8="","",'RAG Run 1'!G8) -> 10 | E13: =IF('RAG Run 2'!G8="","",'RAG Run 2'!G8) -> 10 | F13: =IF('RAG Run 3'!G8="","",'RAG Run 3'!G8) -> 10 | G13: =IF('RAG Run 4'!G8="","",'RAG Run 4'!G8) -> 10 | H13: =IF('RAG Run 5'!G8="","",'RAG Run 5'!G8) -> 10 | I13: =IF(AND(D13=E13,E13=F13,F13=G13,G13=H13),"Yes","No") -> Yes
A14: ='RAG Run 1'!D9 -> Leadership | B14: ='RAG Run 1'!E9 -> LD1.2 | C14: ='RAG Run 1'!F9 -> Foster Collaboration and Teamwork | D14: =IF('RAG Run 1'!G9="","",'RAG Run 1'!G9) -> 8 | E14: =IF('RAG Run 2'!G9="","",'RAG Run 2'!G9) -> 8 | F14: =IF('RAG Run 3'!G9="","",'RAG Run 3'!G9) -> 8 | G14: =IF('RAG Run 4'!G9="","",'RAG Run 4'!G9) -> 8 | H14: =IF('RAG Run 5'!G9="","",'RAG Run 5'!G9) -> 8 | I14: =IF(AND(D14=E14,E14=F14,F14=G14,G14=H14),"Yes","No") -> Yes
A15: ='RAG Run 1'!D10 -> Leadership | B15: ='RAG Run 1'!E10 -> LD1.3 | C15: ='RAG Run 1'!F10 -> Encourage Public Engagement and Participation | D15: =IF('RAG Run 1'!G10="","",'RAG Run 1'!G10) -> 8 | E15: =IF('RAG Run 2'!G10="","",'RAG Run 2'!G10) -> 8 | F15: =IF('RAG Run 3'!G10="","",'RAG Run 3'!G10) -> 8 | G15: =IF('RAG Run 4'!G10="","",'RAG Run 4'!G10) -> 8 | H15: =IF('RAG Run 5'!G10="","",'RAG Run 5'!G10) -> 8 | I15: =IF(AND(D15=E15,E15=F15,F15=G15,G15=H15),"Yes","No") -> Yes
A16: ='RAG Run 1'!D11 -> Leadership | B16: ='RAG Run 1'!E11 -> LD1.4 | C16: ='RAG Run 1'!F11 -> Pursue Byproduct Synergies | D16: =IF('RAG Run 1'!G11="","",'RAG Run 1'!G11) -> 10 | E16: =IF('RAG Run 2'!G11="","",'RAG Run 2'!G11) -> 10 | F16: =IF('RAG Run 3'!G11="","",'RAG Run 3'!G11) -> 10 | G16: =IF('RAG Run 4'!G11="","",'RAG Run 4'!G11) -> 10 | H16: =IF('RAG Run 5'!G11="","",'RAG Run 5'!G11) -> 10 | I16: =IF(AND(D16=E16,E16=F16,F16=G16,G16=H16),"Yes","No") -> Yes
A17: ='RAG Run 1'!D12 -> Leadership | B17: ='RAG Run 1'!E12 -> LD2.1 | C17: ='RAG Run 1'!F12 -> Establish a Sustainability Management Plan | D17: =IF('RAG Run 1'!G12="","",'RAG Run 1'!G12) -> 12 | E17: =IF('RAG Run 2'!G12="","",'RAG Run 2'!G12) -> 12 | F17: =IF('RAG Run 3'!G12="","",'RAG Run 3'!G12) -> 12 | G17: =IF('RAG Run 4'!G12="","",'RAG Run 4'!G12) -> 12 | H17: =IF('RAG Run 5'!G12="","",'RAG Run 5'!G12) -> 14 | I17: =IF(AND(D17=E17,E17=F17,F17=G17,G17=H17),"Yes","No") -> No
A18: ='RAG Run 1'!D13 -> Leadership | B18: ='RAG Run 1'!E13 -> LD2.2 | C18: ='RAG Run 1'!F13 -> Plan for Sustainable Communities | D18: =IF('RAG Run 1'!G13="","",'RAG Run 1'!G13) -> 10 | E18: =IF('RAG Run 2'!G13="","",'RAG Run 2'!G13) -> 10 | F18: =IF('RAG Run 3'!G13="","",'RAG Run 3'!G13) -> 10 | G18: =IF('RAG Run 4'!G13="","",'RAG Run 4'!G13) -> 10 | H18: =IF('RAG Run 5'!G13="","",'RAG Run 5'!G13) -> 12 | I18: =IF(AND(D18=E18,E18=F18,F18=G18,G18=H18),"Yes","No") -> No
... A53: ='RAG Run 1'!D48 -> Resource Allocation | B53: ='RAG Run 1'!E48 -> RA3.4 | C53: ='RAG Run 1'!F48 -> Monitor Water Systems | D53: =IF('RAG Run 1'!G48="","",'RAG Run 1'!G48) -> 8 | E53: =IF('RAG Run 2'!G48="","",'RAG Run 2'!G48) -> 8 | F53: =IF('RAG Run 3'!G48="","",'RAG Run 3'!G48) -> 8 | G53: =IF('RAG Run 4'!G48="","",'RAG Run 4'!G48) -> 6 | H53: =IF('RAG Run 5'!G48="","",'RAG Run 5'!G48) -> 8 | I53: =IF(AND(D53=E53,E53=F53,F53=G53,G53=H53),"Yes","No") -> No
A55: Estimated Level
A56: Category | B56: Credit ID | C56: Credit Name | D56: Run 1 | E56: Run 2 | F56: Run 3 | G56: Run 4 | H56: Run 5 | I56: Consistent?
A57: ='RAG Run 1'!D2 -> Climate And Resilience | B57: ='RAG Run 1'!E2 -> CR2.1 | C57: ='RAG Run 1'!F2 -> Avoid Unsuitable Development | D57: =IF('RAG Run 1'!I2="","",'RAG Run 1'!I2) -> No Level | E57: =IF('RAG Run 2'!I2="","",'RAG Run 2'!I2) -> No Level | F57: =IF('RAG Run 3'!I2="","",'RAG Run 3'!I2) -> Improved | G57: =IF('RAG Run 4'!I2="","",'RAG Run 4'!I2) -> No Level | H57: =IF('RAG Run 5'!I2="","",'RAG Run 5'!I2) -> No Level | I57: =IF(AND(D57=E57,E57=F57,F57=G57,G57=H57),"Yes","No") -> No
A58: ='RAG Run 1'!D3 -> Climate And Resilience | B58: ='RAG Run 1'!E3 -> CR2.2 | C58: ='RAG Run 1'!F3 -> Assess Climate Change Vulnerability | D58: =IF('RAG Run 1'!I3="","",'RAG Run 1'!I3) -> Improved | E58: =IF('RAG Run 2'!I3="","",'RAG Run 2'!I3) -> No Level | F58: =IF('RAG Run 3'!I3="","",'RAG Run 3'!I3) -> Improved | G58: =IF('RAG Run 4'!I3="","",'RAG Run 4'!I3) -> No Level | H58: =IF('RAG Run 5'!I3="","",'RAG Run 5'!I3) -> No Level | I58: =IF(AND(D58=E58,E58=F58,F58=G58,G58=H58),"Yes","No") -> No
A59: ='RAG Run 1'!D4 -> Climate And Resilience | B59: ='RAG Run 1'!E4 -> CR2.3 | C59: ='RAG Run 1'!F4 -> Evaluate Risk and Resilience | D59: =IF('RAG Run 1'!I4="","",'RAG Run 1'!I4) -> No Level | E59: =IF('RAG Run 2'!I4="","",'RAG Run 2'!I4) -> No Level | F59: =IF('RAG Run 3'!I4="","",'RAG Run 3'!I4) -> Improved | G59: =IF('RAG Run 4'!I4="","",'RAG Run 4'!I4) -> No Level | H59: =IF('RAG Run 5'!I4="","",'RAG Run 5'!I4) -> No Level | I59: =IF(AND(D59=E59,E59=F59,F59=G59,G59=H59),"Yes","No") -> No
A60: ='RAG Run 1'!D5 -> Climate And Resilience | B60: ='RAG Run 1'!E5 -> CR2.4 | C60: ='RAG Run 1'!F5 -> Establish Resilience Goals and Strategies | D60: =IF('RAG Run 1'!I5="","",'RAG Run 1'!I5) -> No Level | E60: =IF('RAG Run 2'!I5="","",'RAG Run 2'!I5) -> No Level | F60: =IF('RAG Run 3'!I5="","",'RAG Run 3'!I5) -> Enhanced | G60: =IF('RAG Run 4'!I5="","",'RAG Run 4'!I5) -> No Level | H60: =IF('RAG Run 5'!I5="","",'RAG Run 5'!I5) -> No Level | I60: =IF(AND(D60=E60,E60=F60,F60=G60,G60=H60),"Yes","No") -> No
A61: ='RAG Run 1'!D6 -> Climate And Resilience | B61: ='RAG Run 1'!E6 -> CR2.5 | C61: ='RAG Run 1'!F6 -> Maximize Resilience | D61: =IF('RAG Run 1'!I6="","",'RAG Run 1'!I6) -> No Level | E61: =IF('RAG Run 2'!I6="","",'RAG Run 2'!I6) -> No Level | F61: =IF('RAG Run 3'!I6="","",'RAG Run 3'!I6) -> Enhanced | G61: =IF('RAG Run 4'!I6="","",'RAG Run 4'!I6) -> No Level | H61: =IF('RAG Run 5'!I6="","",'RAG Run 5'!I6) -> No Level | I61: =IF(AND(D61=E61,E61=F61,F61=G61,G61=H61),"Yes","No") -> No
A62: ='RAG Run 1'!D7 -> Climate And Resilience | B62: ='RAG Run 1'!E7 -> CR2.6 | C62: ='RAG Run 1'!F7 -> Improve Infrastructure Integration | D62: =IF('RAG Run 1'!I7="","",'RAG Run 1'!I7) -> No Level | E62: =IF('RAG Run 2'!I7="","",'RAG Run 2'!I7) -> No Level | F62: =IF('RAG Run 3'!I7="","",'RAG Run 3'!I7) -> Improved | G62: =IF('RAG Run 4'!I7="","",'RAG Run 4'!I7) -> No Level | H62: =IF('RAG Run 5'!I7="","",'RAG Run 5'!I7) -> No Level | I62: =IF(AND(D62=E62,E62=F62,F62=G62,G62=H62),"Yes","No") -> No
A63: ='RAG Run 1'!D8 -> Leadership | B63: ='RAG Run 1'!E8 -> LD1.1 | C63: ='RAG Run 1'!F8 -> Provide Effective Leadership and Commitment | D63: =IF('RAG Run 1'!I8="","",'RAG Run 1'!I8) -> Improved | E63: =IF('RAG Run 2'!I8="","",'RAG Run 2'!I8) -> Improved | F63: =IF('RAG Run 3'!I8="","",'RAG Run 3'!I8) -> Improved | G63: =IF('RAG Run 4'!I8="","",'RAG Run 4'!I8) -> Improved | H63: =IF('RAG Run 5'!I8="","",'RAG Run 5'!I8) -> Improved | I63: =IF(AND(D63=E63,E63=F63,F63=G63,G63=H63),"Yes","No") -> Yes
A64: ='RAG Run 1'!D9 -> Leadership | B64: ='RAG Run 1'!E9 -> LD1.2 | C64: ='RAG Run 1'!F9 -> Foster Collaboration and Teamwork | D64: =IF('RAG Run 1'!I9="","",'RAG Run 1'!I9) -> Improved | E64: =IF('RAG Run 2'!I9="","",'RAG Run 2'!I9) -> Improved | F64: =IF('RAG Run 3'!I9="","",'RAG Run 3'!I9) -> Improved | G64: =IF('RAG Run 4'!I9="","",'RAG Run 4'!I9) -> Improved | H64: =IF('RAG Run 5'!I9="","",'RAG Run 5'!I9) -> Improved | I64: =IF(AND(D64=E64,E64=F64,F64=G64,G64=H64),"Yes","No") -> Yes
A65: ='RAG Run 1'!D10 -> Leadership | B65: ='RAG Run 1'!E10 -> LD1.3 | C65: ='RAG Run 1'!F10 -> Encourage Public Engagement and Participation | D65: =IF('RAG Run 1'!I10="","",'RAG Run 1'!I10) -> No Level | E65: =IF('RAG Run 2'!I10="","",'RAG Run 2'!I10) -> No Level | F65: =IF('RAG Run 3'!I10="","",'RAG Run 3'!I10) -> No Level | G65: =IF('RAG Run 4'!I10="","",'RAG Run 4'!I10) -> No Level | H65: =IF('RAG Run 5'!I10="","",'RAG Run 5'!I10) -> No Level | I65: =IF(AND(D65=E65,E65=F65,F65=G65,G65=H65),"Yes","No") -> Yes
A66: ='RAG Run 1'!D11 -> Leadership | B66: ='RAG Run 1'!E11 -> LD1.4 | C66: ='RAG Run 1'!F11 -> Pursue Byproduct Synergies | D66: =IF('RAG Run 1'!I11="","",'RAG Run 1'!I11) -> No Level | E66: =IF('RAG Run 2'!I11="","",'RAG Run 2'!I11) -> No Level | F66: =IF('RAG Run 3'!I11="","",'RAG Run 3'!I11) -> No Level | G66: =IF('RAG Run 4'!I11="","",'RAG Run 4'!I11) -> No Level | H66: =IF('RAG Run 5'!I11="","",'RAG Run 5'!I11) -> No Level | I66: =IF(AND(D66=E66,E66=F66,F66=G66,G66=H66),"Yes","No") -> Yes
A67: ='RAG Run 1'!D12 -> Leadership | B67: ='RAG Run 1'!E12 -> LD2.1 | C67: ='RAG Run 1'!F12 -> Establish a Sustainability Management Plan | D67: =IF('RAG Run 1'!I12="","",'RAG Run 1'!I12) -> No Level | E67: =IF('RAG Run 2'!I12="","",'RAG Run 2'!I12) -> No Level | F67: =IF('RAG Run 3'!I12="","",'RAG Run 3'!I12) -> No Level | G67: =IF('RAG Run 4'!I12="","",'RAG Run 4'!I12) -> No Level | H67: =IF('RAG Run 5'!I12="","",'RAG Run 5'!I12) -> No Level | I67: =IF(AND(D67=E67,E67=F67,F67=G67,G67=H67),"Yes","No") -> Yes
A68: ='RAG Run 1'!D13 -> Leadership | B68: ='RAG Run 1'!E13 -> LD2.2 | C68: ='RAG Run 1'!F13 -> Plan for Sustainable Communities | D68: =IF('RAG Run 1'!I13="","",'RAG Run 1'!I13) -> No Level | E68: =IF('RAG Run 2'!I13="","",'RAG Run 2'!I13) -> No Level | F68: =IF('RAG Run 3'!I13="","",'RAG Run 3'!I13) -> No Level | G68: =IF('RAG Run 4'!I13="","",'RAG Run 4'!I13) -> No Level | H68: =IF('RAG Run 5'!I13="","",'RAG Run 5'!I13) -> No Level | I68: =IF(AND(D68=E68,E68=F68,F68=G68,G68=H68),"Yes","No") -> Yes
... A103: ='RAG Run 1'!D48 -> Resource Allocation | B103: ='RAG Run 1'!E48 -> RA3.4 | C103: ='RAG Run 1'!F48 -> Monitor Water Systems | D103: =IF('RAG Run 1'!I48="","",'RAG Run 1'!I48) -> No Level | E103: =IF('RAG Run 2'!I48="","",'RAG Run 2'!I48) -> No Level | F103: =IF('RAG Run 3'!I48="","",'RAG Run 3'!I48) -> No Level | G103: =IF('RAG Run 4'!I48="","",'RAG Run 4'!I48) -> No Level | H103: =IF('RAG Run 5'!I48="","",'RAG Run 5'!I48) -> No Level | I103: =IF(AND(D103=E103,E103=F103,F103=G103,G103=H103),"Yes","No") -> Yes
A105: Estimated Points
A106: Category | B106: Credit ID | C106: Credit Name | D106: Run 1 | E106: Run 2 | F106: Run 3 | G106: Run 4 | H106: Run 5 | I106: Consistent?
A107: ='RAG Run 1'!D2 -> Climate And Resilience | B107: ='RAG Run 1'!E2 -> CR2.1 | C107: ='RAG Run 1'!F2 -> Avoid Unsuitable Development | D107: =IF('RAG Run 1'!J2="","",'RAG Run 1'!J2) -> 0 | E107: =IF('RAG Run 2'!J2="","",'RAG Run 2'!J2) -> 0 | F107: =IF('RAG Run 3'!J2="","",'RAG Run 3'!J2) -> 0 | G107: =IF('RAG Run 4'!J2="","",'RAG Run 4'!J2) -> 0 | H107: =IF('RAG Run 5'!J2="","",'RAG Run 5'!J2) -> 0 | I107: =IF(AND(D107=E107,E107=F107,F107=G107,G107=H107),"Yes","No") -> Yes
A108: ='RAG Run 1'!D3 -> Climate And Resilience | B108: ='RAG Run 1'!E3 -> CR2.2 | C108: ='RAG Run 1'!F3 -> Assess Climate Change Vulnerability | D108: =IF('RAG Run 1'!J3="","",'RAG Run 1'!J3) -> 8 | E108: =IF('RAG Run 2'!J3="","",'RAG Run 2'!J3) -> 0 | F108: =IF('RAG Run 3'!J3="","",'RAG Run 3'!J3) -> 0 | G108: =IF('RAG Run 4'!J3="","",'RAG Run 4'!J3) -> 0 | H108: =IF('RAG Run 5'!J3="","",'RAG Run 5'!J3) -> 0 | I108: =IF(AND(D108=E108,E108=F108,F108=G108,G108=H108),"Yes","No") -> No
A109: ='RAG Run 1'!D4 -> Climate And Resilience | B109: ='RAG Run 1'!E4 -> CR2.3 | C109: ='RAG Run 1'!F4 -> Evaluate Risk and Resilience | D109: =IF('RAG Run 1'!J4="","",'RAG Run 1'!J4) -> 0 | E109: =IF('RAG Run 2'!J4="","",'RAG Run 2'!J4) -> 0 | F109: =IF('RAG Run 3'!J4="","",'RAG Run 3'!J4) -> 0 | G109: =IF('RAG Run 4'!J4="","",'RAG Run 4'!J4) -> 0 | H109: =IF('RAG Run 5'!J4="","",'RAG Run 5'!J4) -> 0 | I109: =IF(AND(D109=E109,E109=F109,F109=G109,G109=H109),"Yes","No") -> Yes
A110: ='RAG Run 1'!D5 -> Climate And Resilience | B110: ='RAG Run 1'!E5 -> CR2.4 | C110: ='RAG Run 1'!F5 -> Establish Resilience Goals and Strategies | D110: =IF('RAG Run 1'!J5="","",'RAG Run 1'!J5) -> 0 | E110: =IF('RAG Run 2'!J5="","",'RAG Run 2'!J5) -> 0 | F110: =IF('RAG Run 3'!J5="","",'RAG Run 3'!J5) -> 0 | G110: =IF('RAG Run 4'!J5="","",'RAG Run 4'!J5) -> 0 | H110: =IF('RAG Run 5'!J5="","",'RAG Run 5'!J5) -> 0 | I110: =IF(AND(D110=E110,E110=F110,F110=G110,G110=H110),"Yes","No") -> Yes
A111: ='RAG Run 1'!D6 -> Climate And Resilience | B111: ='RAG Run 1'!E6 -> CR2.5 | C111: ='RAG Run 1'!F6 -> Maximize Resilience | D111: =IF('RAG Run 1'!J6="","",'RAG Run 1'!J6) -> 0 | E111: =IF('RAG Run 2'!J6="","",'RAG Run 2'!J6) -> 0 | F111: =IF('RAG Run 3'!J6="","",'RAG Run 3'!J6) -> 0 | G111: =IF('RAG Run 4'!J6="","",'RAG Run 4'!J6) -> 0 | H111: =IF('RAG Run 5'!J6="","",'RAG Run 5'!J6) -> 0 | I111: =IF(AND(D111=E111,E111=F111,F111=G111,G111=H111),"Yes","No") -> Yes
...

Sheet RAG Run 1
A1: Arm | B1: Run | C1: File | D1: Category | E1: Credit ID | F1: Credit Name | G1: Max Points | H1: Applicability | I1: Estimated Level | J1: Estimated Points | K1: % Achieved | L1: Justification | M1: Questions Summary | N1: Level Guide Reference | O1: Concept Phase Actions | P1: Documentation Needed | Q1: Input Tokens | R1: Output Tokens | S1: Elapsed (s) | T1: Valid JSON | U1: Truncated | V1: Success
A2: rag | B2: 1 | C2: 00_sample_project | D2: Climate And Resilience | E2: CR2.1 | F2: Avoid Unsuitable Development | G2: 14 | H2: Applicable | I2: No Level | J2: 0 | K2: 0 | M2: QA:Insufficient Data(No information on site selection process) | QB:Insufficient Data(No environmental impact assessment available) | N2: A + B required for Improved | O2: Conduct site selection process with environmental considerations; Perform environmental impact assessment | P2: Site selection report; Environmental impact assessment | Q2: 17617 | R2: 1284 | S2: 366.91 | T2: TRUE | U2: FALSE | V2: TRUE
A3: rag | B3: 1 | C3: 00_sample_project | D3: Climate And Resilience | E3: CR2.2 | F3: Assess Climate Change Vulnerability | G3: 20 | H3: Applicable | I3: Improved | J3: 8 | K3: 40 | M3: QA:Likely Yes(Project location in Brownsville, PA, suggests potential climate change impacts) | QB:Insufficient Data(No vulnerability assessment available) | N3: A + B required for Improved | O3: Conduct climate change vulnerability assessment | P3: Climate change vulnerability assessment report | Q3: 17617 | R3: 1284 | S3: 366.91 | T3: TRUE | U3: FALSE | V3: TRUE
A4: rag | B4: 1 | C4: 00_sample_project | D4: Climate And Resilience | E4: CR2.3 | F4: Evaluate Risk and Resilience | G4: 26 | H4: Applicable | I4: No Level | J4: 0 | K4: 0 | M4: QA:Insufficient Data(No risk assessment available) | QB:Insufficient Data(No identification of critical functions and dependencies) | N4: A + B + C + D + E required for Conserving | O4: Conduct risk assessment; Identify critical functions and dependencies | P4: Risk assessment report; Critical functions and dependencies identification document | Q4: 17617 | R4: 1284 | S4: 366.91 | T4: TRUE | U4: FALSE | V4: TRUE
A5: rag | B5: 1 | C5: 00_sample_project | D5: Climate And Resilience | E5: CR2.4 | F5: Establish Resilience Goals and Strategies | G5: 20 | H5: Applicable | I5: No Level | J5: 0 | K5: 0 | M5: QA:Insufficient Data(No project performance goals available) | QB:Insufficient Data(No risk management strategies developed) | N5: A + B required for Enhanced | O5: Develop project performance goals; Establish risk management strategies | P5: Project performance goals document; Risk management strategies report | Q5: 17617 | R5: 1284 | S5: 366.91 | T5: TRUE | U5: FALSE | V5: TRUE
A6: rag | B6: 1 | C6: 00_sample_project | D6: Climate And Resilience | E6: CR2.5 | F6: Maximize Resilience | G6: 26 | H6: Applicable | I6: No Level | J6: 0 | K6: 0 | M6: QA:Insufficient Data(No resilience goals and strategies developed) | QB:Insufficient Data(No implementation of resilience strategies) | N6: A + B + C + D + E required for Conserving | O6: Develop resilience goals and strategies; Implement resilience strategies | P6: Resilience goals and strategies document; Resilience strategies implementation report | Q6: 17617 | R6: 1284 | S6: 366.91 | T6: TRUE | U6: FALSE | V6: TRUE
A7: rag | B7: 1 | C7: 00_sample_project | D7: Climate And Resilience | E7: CR2.6 | F7: Improve Infrastructure Integration | G7: 18 | H7: Applicable | I7: No Level | J7: 0 | K7: 0 | M7: QA:Insufficient Data(No consideration of infrastructure integration) | QB:Insufficient Data(No evaluation of systems performance) | N7: A + B required for Improved | O7: Consider infrastructure integration; Evaluate systems performance | P7: Infrastructure integration report; Systems performance evaluation document | Q7: 17617 | R7: 1284 | S7: 366.91 | T7: TRUE | U7: FALSE | V7: TRUE
A8: rag | B8: 1 | C8: 00_sample_project | D8: Leadership | E8: LD1.1 | F8: Provide Effective Leadership and Commitment | G8: 10 | H8: Applicable | I8: Improved | J8: 2 | K8: 20 | M8: QA:Likely Yes(Project team includes multiple stakeholders (Cartesian Inverse, PA; Etienne Oise) | QB:Insufficient Data(No information on sustainability goals or targets) | N8: A + B required for Enhanced | O8: Develop sustainability goals and targets | P8: Sustainability management plan; Stakeholder engagement records | Q8: 17191 | R8: 1953 | S8: 542.38 | T8: TRUE | U8: FALSE | V8: TRUE
A9: rag | B9: 1 | C9: 00_sample_project | D9: Leadership | E9: LD1.2 | F9: Foster Collaboration and Teamwork | G9: 8 | H9: Applicable | I9: Improved | J9: 2 | K9: 25 | M9: QA:Likely Yes(Multiple stakeholders involved in project team (Cartesian Inverse, PA; Etienne O) | QB:Insufficient Data(No information on collaboration tools or processes) | N9: A + B required for Enhanced | O9: Establish collaboration tools and processes | P9: Collaboration plan; Meeting minutes | Q9: 17191 | R9: 1953 | S9: 542.38 | T9: TRUE | U9: FALSE | V9: TRUE
A10: rag | B10: 1 | C10: 00_sample_project | D10: Leadership | E10: LD1.3 | F10: Encourage Public Engagement and Participation | G10: 8 | H10: Applicable | I10: No Level | J10: 0 | K10: 0 | M10: QA:Insufficient Data(No information on public engagement or participation) | QB:Insufficient Data(No information on community outreach or education) | N10: A + B required for Improved | O10: Develop public engagement and participation plan | P10: Public engagement plan; Community outreach records | Q10: 17191 | R10: 1953 | S10: 542.38 | T10: TRUE | U10: FALSE | V10: TRUE
A11: rag | B11: 1 | C11: 00_sample_project | D11: Leadership | E11: LD1.4 | F11: Pursue Byproduct Synergies | G11: 10 | H11: Applicable | I11: No Level | J11: 0 | K11: 0 | M11: QA:Insufficient Data(No information on byproduct synergies) | QB:Insufficient Data(No information on waste reduction or material reuse) | N11: A + B required for Improved | O11: Investigate byproduct synergies and waste reduction opportunities | P11: Byproduct synergy plan; Waste reduction strategy | Q11: 17191 | R11: 1953 | S11: 542.38 | T11: TRUE | U11: FALSE | V11: TRUE
A12: rag | B12: 1 | C12: 00_sample_project | D12: Leadership | E12: LD2.1 | F12: Establish a Sustainability Management Plan | G12: 12 | H12: Applicable | I12: No Level | J12: 0 | K12: 0 | M12: QA:Insufficient Data(No information on sustainability management plan) | QB:Insufficient Data(No information on monitoring and reporting processes) | N12: A + B required for Improved | O12: Develop sustainability management plan | P12: Sustainability management plan; Monitoring and reporting records | Q12: 17191 | R12: 1953 | S12: 542.38 | T12: TRUE | U12: FALSE | V12: TRUE
A13: rag | B13: 1 | C13: 00_sample_project | D13: Leadership | E13: LD2.2 | F13: Plan for Sustainable Communities | G13: 10 | H13: Applicable | I13: No Level | J13: 0 | K13: 0 | M13: QA:Insufficient Data(No information on community planning or development) | QB:Insufficient Data(No information on social and economic benefits) | N13: A + B required for Improved | O13: Develop community planning and development strategy | P13: Community plan; Social and economic benefit analysis | Q13: 17191 | R13: 1953 | S13: 542.38 | T13: TRUE | U13: FALSE | V13: TRUE
... A17: rag | B17: 1 | C17: 00_sample_project | D17: Leadership | E17: LD3.3 | F17: Conduct a Life-Cycle Assessment | G17: 12 | H17: Applicable | I17: No Level | J17: 0 | K17: 0 | M17: QA:Insufficient Data(No information on life-cycle assessment) | QB:Insufficient Data(No information on environmental impacts or benefits) | N17: A + B required for Improved | O17: Conduct life-cycle assessment | P17: Life-cycle assessment report; Environmental impact analysis | Q17: 17191 | R17: 1953 | S17: 542.38 | T17: TRUE | U17: FALSE | V17: TRUE
A18: rag | B18: 1 | C18: 00_sample_project | D18: Natural World | E18: NW1.1 | F18: Conserve Natural Areas | G18: 14 | H18: APPLICABLE | I18: No Level | J18: 0 | K18: 0 | L18: The project is located in an area with potential natural habitats and ecosystems, making conservation of natural areas relevant. | M18: QA:Insufficient Data(No information on natural habitat preservation) | QB:Insufficient Data(No data on native plant species used in landscaping) | N18: A + B required for Improved | O18: Conduct site assessment to identify natural habitats; Research local native plant species for landscaping | P18: Site assessment report; Native plant species list | Q18: 17916 | R18: 1349 | S18: 405.26 | T18: TRUE | U18: FALSE | V18: TRUE
A19: rag | B19: 1 | C19: 00_sample_project | D19: Natural World | E19: NW1.2 | F19: Provide Wetland and Surface Water Buffers | G19: 10 | H19: APPLICABLE | I19: No Level | J19: 0 | K19: 0 | L19: The project's location near water bodies makes wetland and surface water buffers relevant. | M19: QA:Insufficient Data(No information on wetland or surface water buffer zones) | QB:Insufficient Data(No data on buffer zone maintenance plans) | N19: A + B required for Improved | O19: Conduct wetland and surface water assessment; Develop buffer zone maintenance plan | P19: Wetland and surface water assessment report; Buffer zone maintenance plan | Q19: 17916 | R19: 1349 | S19: 405.26 | T19: TRUE | U19: FALSE | V19: TRUE
A20: rag | B20: 1 | C20: 00_sample_project | D20: Natural World | E20: NW2.2 | F20: Manage Stormwater | G20: 24 | H20: APPLICABLE | I20: No Level | J20: 0 | K20: 0 | L20: The project's potential impact on stormwater runoff makes management relevant. | M20: QA:Insufficient Data(No information on stormwater management strategies) | QB:Insufficient Data(No data on stormwater runoff reduction targets) | N20: A + B required for Improved | O20: Develop stormwater management plan; Set stormwater runoff reduction targets | P20: Stormwater management plan; Runoff reduction target documentation | Q20: 17916 | R20: 1349 | S20: 405.26 | T20: TRUE | U20: FALSE | V20: TRUE
A21: rag | B21: 1 | C21: 00_sample_project | D21: Natural World | E21: NW2.4 | F21: Protect Surface and Groundwater Quality | G21: 14 | H21: APPLICABLE | I21: No Level | J21: 0 | K21: 0 | L21: The project's potential impact on surface and groundwater quality makes protection relevant. | M21: QA:Insufficient Data(No information on surface and groundwater protection measures) | QB:Insufficient Data(No data on water quality monitoring plans) | N21: A + B required for Improved | O21: Develop surface and groundwater protection plan; Establish water quality monitoring program | P21: Surface and groundwater protection plan; Water quality monitoring plan | Q21: 17916 | R21: 1349 | S21: 405.26 | T21: TRUE | U21: FALSE | V21: TRUE
A22: rag | B22: 1 | C22: 00_sample_project | D22: Natural World | E22: NW3.3 | F22: Maintain Floodplain Functions | G22: 14 | H22: APPLICABLE | I22: No Level | J22: 0 | K22: 0 | L22: The project's location in a floodplain makes maintaining floodplain functions relevant. | M22: QA:Insufficient Data(No information on floodplain function preservation) | QB:Insufficient Data(No data on vegetated zone preservation) | N22: A + B required for Improved | O22: Conduct floodplain function assessment; Develop plan to preserve vegetated zones | P22: Floodplain function assessment report; Vegetated zone preservation plan | Q22: 17916 | R22: 1349 | S22: 405.26 | T22: TRUE | U22: FALSE | V22: TRUE
A23: rag | B23: 1 | C23: 00_sample_project | D23: Natural World | E23: NW3.5 | F23: Protect Soil Health | G23: 10 | H23: APPLICABLE | I23: No Level | J23: 0 | K23: 0 | L23: The project's potential impact on soil health makes protection relevant. | M23: QA:Insufficient Data(No information on soil health protection measures) | QB:Insufficient Data(No data on soil erosion control plans) | N23: A + B required for Improved | O23: Develop soil health protection plan; Establish soil erosion control measures | P23: Soil health protection plan; Soil erosion control plan | Q23: 17916 | R23: 1349 | S23: 405.26 | T23: TRUE | U23: FALSE | V23: TRUE
A24: rag | B24: 1 | C24: 00_sample_project | D24: Quality Of Life | E24: QL1.1 | F24: Improve Community Quality of Life | G24: 26 | H24: Applicable | I24: Improved | J24: 2 | K24: 7.7 | L24: The project is a mixed-use development with residential, commercial, and community spaces, indicating potential for community quality of life improvements. | M24: QA:Likely Yes(Project includes live/work units and community spaces.) | QB:Insufficient Data(Lack of information on community engagement and feedback mechanisms.) | N24: A + B required for Enhanced | O24: Engage with local stakeholders to understand community needs and priorities. | P24: Community engagement records; Stakeholder feedback mechanisms | Q24: 17220 | R24: 2486 | S24: 844.38 | T24: TRUE | U24: FALSE | V24: TRUE
A25: rag | B25: 1 | C25: 00_sample_project | D25: Quality Of Life | E25: QL1.2 | F25: Enhance Public Health & Safety | G25: 20 | H25: Applicable | I25: Improved | J25: 2 | K25: 10 | L25: The project includes residential and commercial spaces, which can impact public health and safety. | M25: QA:Likely Yes(Project includes fire resistive walls and smoke barriers.) | QB:Insufficient Data(Lack of information on emergency response planning and evacuation procedures.) | N25: A + B required for Enhanced | O25: Develop emergency response plan and evacuation procedures. | P25: Emergency response plan; Evacuation procedure documents | Q25: 17220 | R25: 2486 | S25: 844.38 | T25: TRUE | U25: FALSE | V25: TRUE
A26: rag | B26: 1 | C26: 00_sample_project | D26: Quality Of Life | E26: QL1.3 | F26: Improve Construction Safety | G26: 14 | H26: Applicable | I26: Improved | J26: 2 | K26: 14.3 | L26: The project involves construction activities that can impact worker safety. | M26: QA:Likely Yes(Project includes safety protocols for workers.) | QB:Insufficient Data(Lack of information on worker training programs and site-specific hazard assessm) | N26: A + B required for Enhanced | O26: Develop worker training programs and conduct site-specific hazard assessments. | P26: Worker training records; Site-specific hazard assessment reports | Q26: 17220 | R26: 2486 | S26: 844.38 | T26: TRUE | U26: FALSE | V26: TRUE
A27: rag | B27: 1 | C27: 00_sample_project | D27: Quality Of Life | E27: QL1.4 | F27: Minimize Noise & Vibration | G27: 12 | H27: Applicable | I27: Improved | J27: 1 | K27: 8.3 | L27: The project includes residential and commercial spaces that can be impacted by noise and vibration. | M27: QA:Likely Yes(Project includes soundproofing measures.) | QB:Insufficient Data(Lack of information on vibration mitigation strategies.) | N27: A + B required for Enhanced | O27: Investigate vibration mitigation strategies and implement soundproofing measures. | P27: Soundproofing design documents; Vibration mitigation strategy reports | Q27: 17220 | R27: 2486 | S27: 844.38 | T27: TRUE | U27: FALSE | V27: TRUE
A28: rag | B28: 1 | C28: 00_sample_project | D28: Quality Of Life | E28: QL1.5 | F28: Minimize Light Pollution | G28: 12 | H28: Applicable | I28: Improved | J28: 1 | K28: 8.3 | L28: The project includes exterior lighting that can contribute to light pollution. | M28: QA:Likely Yes(Project includes energy-efficient lighting.) | QB:Insufficient Data(Lack of information on lighting design and controls.) | N28: A + B required for Enhanced | O28: Develop lighting design and control strategies to minimize light pollution. | P28: Lighting design documents; Control strategy reports | Q28: 17220 | R28: 2486 | S28: 844.38 | T28: TRUE | U28: FALSE | V28: TRUE
A29: rag | B29: 1 | C29: 00_sample_project | D29: Quality Of Life | E29: QL1.6 | F29: Minimize Construction Impacts | G29: 8 | H29: Applicable | I29: Improved | J29: 1 | K29: 12.5 | L29: The project involves construction activities that can impact the surrounding environment. | M29: QA:Likely Yes(Project includes waste management plan.) | QB:Insufficient Data(Lack of information on construction sequencing and scheduling.) | N29: A + B required for Enhanced | O29: Develop construction sequencing and scheduling strategies to minimize impacts. | P29: Construction sequencing documents; Scheduling reports | Q29: 17220 | R29: 2486 | S29: 844.38 | T29: TRUE | U29: FALSE | V29: TRUE
... A33: rag | B33: 1 | C33: 00_sample_project | D33: Quality Of Life | E33: QL3.1 | F33: Advance Equity & Social Justice | G33: 18 | H33: Applicable | I33: Improved | J33: 3 | K33: 16.7 | L33: The project includes community spaces that can impact equity and social justice. | M33: QA:Likely Yes(Project includes community engagement and outreach.) | QB:Insufficient Data(Lack of information on inclusive design principles and social impact assessments) | N33: A + B required for Enhanced | O33: Investigate inclusive design principles and social impact assessments. | P33: Inclusive design principle reports; Social impact assessment documents | Q33: 17220 | R33: 2486 | S33: 844.38 | T33: TRUE | U33: FALSE | V33: TRUE
A34: rag | B34: 1 | C34: 00_sample_project | D34: Quality Of Life | E34: QL3.2 | F34: Preserve Historic & Cultural Resources | G34: 18 | H34: Not Applicable | J34: 0 | K34: 0 | L34: The project does not involve historic or cultural resources. | Q34: 17220 | R34: 2486 | S34: 844.38 | T34: TRUE | U34: FALSE | V34: TRUE
A35: rag | B35: 1 | C35: 00_sample_project | D35: Quality Of Life | E35: QL3.3 | F35: Enhance Views & Local Character | G35: 14 | H35: Applicable | I35: Improved | J35: 1 | K35: 7.1 | L35: The project includes public spaces that can impact views and local character. | M35: QA:Likely Yes(Project includes design elements that enhance local character.) | QB:Insufficient Data(Lack of information on view preservation and enhancement strategies.) | N35: A + B required for Enhanced | O35: Investigate view preservation and enhancement strategies. | P35: View preservation reports; Enhancement strategy documents | Q35: 17220 | R35: 2486 | S35: 844.38 | T35: TRUE | U35: FALSE | V35: TRUE
A36: rag | B36: 1 | C36: 00_sample_project | D36: Resource Allocation | E36: RA1.1 | F36: Reduce Materials Use | G36: 12 | H36: Applicable | I36: No Level | J36: 0 | K36: 0 | M36: QA:Insufficient Data(No material takeoff or bill of quantities in the model) | QB:Insufficient Data(No information on recycled content or sustainable materials) | N36: A + B required for Improved | O36: Develop a material takeoff and bill of quantities; Research sustainable materials and recycled content options | P36: Material takeoff and bill of quantities; Sustainable materials and recycled content research | Q36: 17210 | R36: 2640 | S36: 929.49 | T36: TRUE | U36: FALSE | V36: TRUE
A37: rag | B37: 1 | C37: 00_sample_project | D37: Resource Allocation | E37: RA1.2 | F37: Use Recycled Materials | G37: 10 | H37: Applicable | I37: No Level | J37: 0 | K37: 0 | M37: QA:Insufficient Data(No information on recycled materials used in the project) | QB:Insufficient Data(No documentation of recycled material quantities) | N37: A + B required for Improved | O37: Research recycled material options; Develop a plan for incorporating recycled materials into the project | P37: Recycled material research; Plan for incorporating recycled materials | Q37: 17210 | R37: 2640 | S37: 929.49 | T37: TRUE | U37: FALSE | V37: TRUE
A38: rag | B38: 1 | C38: 00_sample_project | D38: Resource Allocation | E38: RA1.3 | F38: Reduce Operational Waste | G38: 8 | H38: Applicable | I38: No Level | J38: 0 | K38: 0 | M38: QA:Insufficient Data(No information on operational waste reduction strategies) | QB:Insufficient Data(No documentation of waste reduction goals or targets) | N38: A + B required for Improved | O38: Develop a plan for reducing operational waste; Research waste reduction strategies and technologies | P38: Operational waste reduction plan; Waste reduction goals or targets | Q38: 17210 | R38: 2640 | S38: 929.49 | T38: TRUE | U38: FALSE | V38: TRUE
A39: rag | B39: 1 | C39: 00_sample_project | D39: Resource Allocation | E39: RA1.4 | F39: Reduce Construction Waste | G39: 10 | H39: Applicable | I39: No Level | J39: 0 | K39: 0 | M39: QA:Insufficient Data(No information on construction waste reduction strategies) | QB:Insufficient Data(No documentation of waste reduction goals or targets) | N39: A + B required for Improved | O39: Develop a plan for reducing construction waste; Research waste reduction strategies and technologies | P39: Construction waste reduction plan; Waste reduction goals or targets | Q39: 17210 | R39: 2640 | S39: 929.49 | T39: TRUE | U39: FALSE | V39: TRUE
A40: rag | B40: 1 | C40: 00_sample_project | D40: Resource Allocation | E40: RA1.5 | F40: Balance Earthwork On Site | G40: 6 | H40: Applicable | I40: No Level | J40: 0 | K40: 0 | M40: QA:Insufficient Data(No information on earthwork balancing strategies) | QB:Insufficient Data(No documentation of earthwork balancing goals or targets) | N40: A + B required for Improved | O40: Develop a plan for balancing earthwork on site; Research earthwork balancing strategies and technologies | P40: Earthwork balancing plan; Earthwork balancing goals or targets | Q40: 17210 | R40: 2640 | S40: 929.49 | T40: TRUE | U40: FALSE | V40: TRUE
A41: rag | B41: 1 | C41: 00_sample_project | D41: Resource Allocation | E41: RA2.1 | F41: Reduce Operational Energy Consumption | G41: 20 | H41: Applicable | I41: No Level | J41: 0 | K41: 0 | M41: QA:Insufficient Data(No information on operational energy consumption reduction strategies) | QB:Insufficient Data(No documentation of energy reduction goals or targets) | N41: A + B required for Improved | O41: Develop a plan for reducing operational energy consumption; Research energy reduction strategies and technologies | P41: Operational energy reduction plan; Energy reduction goals or targets | Q41: 17210 | R41: 2640 | S41: 929.49 | T41: TRUE | U41: FALSE | V41: TRUE
A42: rag | B42: 1 | C42: 00_sample_project | D42: Resource Allocation | E42: RA2.2 | F42: Reduce Construction Energy Consumption | G42: 12 | H42: Applicable | I42: No Level | J42: 0 | K42: 0 | M42: QA:Insufficient Data(No information on construction energy consumption reduction strategies) | QB:Insufficient Data(No documentation of energy reduction goals or targets) | N42: A + B required for Improved | O42: Develop a plan for reducing construction energy consumption; Research energy reduction strategies and technologies | P42: Construction energy reduction plan; Energy reduction goals or targets | Q42: 17210 | R42: 2640 | S42: 929.49 | T42: TRUE | U42: FALSE | V42: TRUE
A43: rag | B43: 1 | C43: 00_sample_project | D43: Resource Allocation | E43: RA2.3 | F43: Use Renewable Energy | G43: 10 | H43: Applicable | I43: No Level | J43: 0 | K43: 0 | M43: QA:Insufficient Data(No information on renewable energy sources) | QB:Insufficient Data(No documentation of renewable energy goals or targets) | N43: A + B required for Improved | O43: Research renewable energy sources; Develop a plan for incorporating renewable energy into the project | P43: Renewable energy research; Plan for incorporating renewable energy | Q43: 17210 | R43: 2640 | S43: 929.49 | T43: TRUE | U43: FALSE | V43: TRUE
A44: rag | B44: 1 | C44: 00_sample_project | D44: Resource Allocation | E44: RA2.4 | F44: Commission and Monitor Energy Systems | G44: 8 | H44: Applicable | I44: No Level | J44: 0 | K44: 0 | M44: QA:Insufficient Data(No information on energy system commissioning or monitoring) | QB:Insufficient Data(No documentation of energy system performance goals or targets) | N44: A + B required for Improved | O44: Develop a plan for commissioning and monitoring energy systems; Research energy system performance metrics | P44: Energy system commissioning and monitoring plan; Energy system performance goals or targets | Q44: 17210 | R44: 2640 | S44: 929.49 | T44: TRUE | U44: FALSE | V44: TRUE
A45: rag | B45: 1 | C45: 00_sample_project | D45: Resource Allocation | E45: RA3.1 | F45: Preserve Water Resources | G45: 14 | H45: Applicable | I45: No Level | J45: 0 | K45: 0 | M45: QA:Insufficient Data(No information on water conservation strategies) | QB:Insufficient Data(No documentation of water reduction goals or targets) | N45: A + B required for Improved | O45: Develop a plan for preserving water resources; Research water conservation strategies and technologies | P45: Water preservation plan; Water reduction goals or targets | Q45: 17210 | R45: 2640 | S45: 929.49 | T45: TRUE | U45: FALSE | V45: TRUE
A46: rag | B46: 1 | C46: 00_sample_project | D46: Resource Allocation | E46: RA3.2 | F46: Reduce Operational Water Consumption | G46: 12 | H46: Applicable | I46: No Level | J46: 0 | K46: 0 | M46: QA:Insufficient Data(No information on operational water consumption reduction strategies) | QB:Insufficient Data(No documentation of water reduction goals or targets) | N46: A + B required for Improved | O46: Develop a plan for reducing operational water consumption; Research water reduction strategies and technologies | P46: Operational water reduction plan; Water reduction goals or targets | Q46: 17210 | R46: 2640 | S46: 929.49 | T46: TRUE | U46: FALSE | V46: TRUE
...

Sheet RAG Run 2
A1: Arm | B1: Run | C1: File | D1: Category | E1: Credit ID | F1: Credit Name | G1: Max Points | H1: Applicability | I1: Estimated Level | J1: Estimated Points | K1: % Achieved | L1: Justification | M1: Questions Summary | N1: Level Guide Reference | O1: Concept Phase Actions | P1: Documentation Needed | Q1: Input Tokens | R1: Output Tokens | S1: Elapsed (s) | T1: Valid JSON | U1: Truncated | V1: Success
A2: rag | B2: 2 | C2: 00_sample_project | D2: Climate And Resilience | E2: CR2.1 | F2: Avoid Unsuitable Development | G2: 14 | H2: APPLICABLE | I2: No Level | J2: 0 | K2: 0 | L2: The project is located in Brownsville, PA, and has a significant impact on the community. It would be difficult to demonstrate that this credit is not relevant or applicable. | M2: QA:Insufficient Data(No information on site selection process) | QB:Insufficient Data(No information on environmental impact assessment) | N2: A + B required for Improved | O2: Conduct site selection process; Perform environmental impact assessment | P2: Site selection report; Environmental impact assessment report | Q2: 17617 | R2: 1700 | S2: 610.15 | T2: TRUE | U2: FALSE | V2: TRUE
A3: rag | B3: 2 | C3: 00_sample_project | D3: Climate And Resilience | E3: CR2.2 | F3: Assess Climate Change Vulnerability | G3: 20 | H3: APPLICABLE | I3: No Level | J3: 0 | K3: 0 | L3: The project is potentially impacted by climate change, and it would be difficult to demonstrate that this credit is not relevant or applicable. | M3: QA:Insufficient Data(No information on climate change threats) | QB:Insufficient Data(No information on project vulnerability) | QC:Insufficient Data(No information on infrastructure system vulnerability) | QD:Insufficient Data(No information on community vulnerability) | QE:Insufficient Data(No information on sharing climate threat findings) | N3: A + B required for Improved | O3: Conduct climate change vulnerability assessment; Identify project and infrastructure system vulnerabilities | P3: Climate change vulnerability assessment report; Project and infrastructure system vulnerability reports | Q3: 17617 | R3: 1700 | S3: 610.15 | T3: TRUE | U3: FALSE | V3: TRUE
A4: rag | B4: 2 | C4: 00_sample_project | D4: Climate And Resilience | E4: CR2.3 | F4: Evaluate Risk and Resilience | G4: 26 | H4: APPLICABLE | I4: No Level | J4: 0 | K4: 0 | L4: The project is exposed to risks, and it would be difficult to demonstrate that this credit is not relevant or applicable. | M4: QA:Insufficient Data(No information on risk assessment) | QB:Insufficient Data(No information on critical functions and dependencies) | QC:Insufficient Data(No information on threats or hazards) | QD:Insufficient Data(No information on vulnerabilities of critical functions and dependencies) | QE:Insufficient Data(No information on risk evaluation) | QF:Insufficient Data(No information on stakeholder participation in risk evaluation) | N4: A + B + C + D + E required for Improved | O4: Conduct risk assessment; Identify critical functions and dependencies; Evaluate risks | P4: Risk assessment report; Critical functions and dependencies report; Risk evaluation report | Q4: 17617 | R4: 1700 | S4: 610.15 | T4: TRUE | U4: FALSE | V4: TRUE
A5: rag | B5: 2 | C5: 00_sample_project | D5: Climate And Resilience | E5: CR2.4 | F5: Establish Resilience Goals and Strategies | G5: 20 | H5: APPLICABLE | I5: No Level | J5: 0 | K5: 0 | L5: The project is exposed to risks, and it would be difficult to demonstrate that this credit is not relevant or applicable. | M5: QA:Insufficient Data(No information on project performance goals and risk appetite) | QB:Insufficient Data(No information on risk management strategies) | QC:Insufficient Data(No information on stakeholder engagement in developing resilience goals) | QD:Insufficient Data(No information on community resilience or climate change adaptation goals) | N5: A + B required for Enhanced | O5: Establish project performance goals and risk appetite; Develop risk management strategies | P5: Project performance goals and risk appetite report; Risk management strategies report | Q5: 17617 | R5: 1700 | S5: 610.15 | T5: TRUE | U5: FALSE | V5: TRUE
A6: rag | B6: 2 | C6: 00_sample_project | D6: Climate And Resilience | E6: CR2.5 | F6: Maximize Resilience | G6: 26 | H6: APPLICABLE | I6: No Level | J6: 0 | K6: 0 | L6: The project is exposed to risks, and it would be difficult to demonstrate that this credit is not relevant or applicable. | M6: QA:Insufficient Data(No information on resilience goals and strategies) | QB:Insufficient Data(No information on implementation of resilience strategies) | QC:Insufficient Data(No information on monitoring and review of resilience strategies) | QD:Insufficient Data(No information on incorporation of resilience goals and strategies into operatio) | QE:Insufficient Data(No information on methods for measuring or quantifying resilience performance ta) | N6: A + B required for Improved | O6: Develop resilience goals and strategies; Implement resilience strategies | P6: Resilience goals and strategies report; Implementation of resilience strategies report | Q6: 17617 | R6: 1700 | S6: 610.15 | T6: TRUE | U6: FALSE | V6: TRUE
A7: rag | B7: 2 | C7: 00_sample_project | D7: Climate And Resilience | E7: CR2.6 | F7: Improve Infrastructure Integration | G7: 18 | H7: APPLICABLE | I7: No Level | J7: 0 | K7: 0 | L7: The project is part of a larger infrastructure system, and it would be difficult to demonstrate that this credit is not relevant or applicable. | M7: QA:Insufficient Data(No information on infrastructure integration) | N7: A required for Improved | O7: Improve infrastructure integration | P7: Infrastructure integration report | Q7: 17617 | R7: 1700 | S7: 610.15 | T7: TRUE | U7: FALSE | V7: TRUE
A8: rag | B8: 2 | C8: 00_sample_project | D8: Leadership | E8: LD1.1 | F8: Provide Effective Leadership and Commitment | G8: 10 | H8: Applicable | I8: Improved | J8: 2 | K8: 20 | M8: QA:Likely Yes(Project team includes multiple stakeholders (Cartesian Inverse, PA; Etienne Oise) | QB:Insufficient Data(No information on sustainability goals or targets) | N8: A + B required for Enhanced | O8: Develop sustainability goals and targets | P8: Sustainability management plan; Stakeholder engagement records | Q8: 17191 | R8: 1954 | S8: 693.75 | T8: TRUE | U8: FALSE | V8: TRUE
A9: rag | B9: 2 | C9: 00_sample_project | D9: Leadership | E9: LD1.2 | F9: Foster Collaboration and Teamwork | G9: 8 | H9: Applicable | I9: Improved | J9: 2 | K9: 25 | M9: QA:Likely Yes(Multiple stakeholders involved in project team (Cartesian Inverse, PA; Etienne O) | QB:Insufficient Data(No information on collaboration tools or processes) | N9: A + B required for Enhanced | O9: Establish collaboration tools and processes | P9: Collaboration plan; Meeting minutes | Q9: 17191 | R9: 1954 | S9: 693.75 | T9: TRUE | U9: FALSE | V9: TRUE
A10: rag | B10: 2 | C10: 00_sample_project | D10: Leadership | E10: LD1.3 | F10: Encourage Public Engagement and Participation | G10: 8 | H10: Applicable | I10: No Level | J10: 0 | K10: 0 | M10: QA:Insufficient Data(No information on public engagement or participation) | QB:Insufficient Data(No information on community outreach or education) | N10: A + B required for Improved | O10: Develop public engagement and participation plan | P10: Public engagement plan; Community outreach records | Q10: 17191 | R10: 1954 | S10: 693.75 | T10: TRUE | U10: FALSE | V10: TRUE
A11: rag | B11: 2 | C11: 00_sample_project | D11: Leadership | E11: LD1.4 | F11: Pursue Byproduct Synergies | G11: 10 | H11: Applicable | I11: No Level | J11: 0 | K11: 0 | M11: QA:Insufficient Data(No information on byproduct synergies) | QB:Insufficient Data(No information on waste reduction or material reuse) | N11: A + B required for Improved | O11: Investigate byproduct synergies and waste reduction opportunities | P11: Byproduct synergy plan; Waste reduction strategy | Q11: 17191 | R11: 1954 | S11: 693.75 | T11: TRUE | U11: FALSE | V11: TRUE
A12: rag | B12: 2 | C12: 00_sample_project | D12: Leadership | E12: LD2.1 | F12: Establish a Sustainability Management Plan | G12: 12 | H12: Applicable | I12: No Level | J12: 0 | K12: 0 | M12: QA:Insufficient Data(No information on sustainability management plan) | QB:Insufficient Data(No information on monitoring and reporting processes) | N12: A + B required for Improved | O12: Develop sustainability management plan | P12: Sustainability management plan; Monitoring and reporting records | Q12: 17191 | R12: 1954 | S12: 693.75 | T12: TRUE | U12: FALSE | V12: TRUE
A13: rag | B13: 2 | C13: 00_sample_project | D13: Leadership | E13: LD2.2 | F13: Plan for Sustainable Communities | G13: 10 | H13: Applicable | I13: No Level | J13: 0 | K13: 0 | M13: QA:Insufficient Data(No information on community planning or development) | QB:Insufficient Data(No information on social and economic benefits) | N13: A + B required for Improved | O13: Develop community planning and development strategy | P13: Community plan; Social and economic impact assessment | Q13: 17191 | R13: 1954 | S13: 693.75 | T13: TRUE | U13: FALSE | V13: TRUE
A14: rag | B14: 2 | C14: 00_sample_project | D14: Leadership | E14: LD2.3 | F14: Conduct a Life-Cycle Economic Evaluation | G14: 12 | H14: Applicable | I14: No Level | J14: 0 | K14: 0 | M14: QA:Insufficient Data(No information on life-cycle economic evaluation) | QB:Insufficient Data(No information on cost-benefit analysis or return on investment) | N14: A + B required for Improved | O14: Conduct life-cycle economic evaluation | P14: Life-cycle economic evaluation report; Cost-benefit analysis | Q14: 17191 | R14: 1954 | S14: 693.75 | T14: TRUE | U14: FALSE | V14: TRUE
A15: rag | B15: 2 | C15: 00_sample_project | D15: Leadership | E15: LD3.1 | F15: Encourage Sustainable Procurement Practices | G15: 10 | H15: Applicable | I15: No Level | J15: 0 | K15: 0 | M15: QA:Insufficient Data(No information on sustainable procurement practices) | QB:Insufficient Data(No information on environmentally responsible purchasing) | N15: A + B required for Improved | O15: Develop sustainable procurement plan | P15: Sustainable procurement plan; Environmentally responsible purchasing records | Q15: 17191 | R15: 1954 | S15: 693.75 | T15: TRUE | U15: FALSE | V15: TRUE
A16: rag | B16: 2 | C16: 00_sample_project | D16: Leadership | E16: LD3.2 | F16: Support Local and Regional Economies | G16: 8 | H16: Applicable | I16: No Level | J16: 0 | K16: 0 | M16: QA:Insufficient Data(No information on local or regional economic benefits) | QB:Insufficient Data(No information on community development or job creation) | N16: A + B required for Improved | O16: Develop local and regional economic development strategy | P16: Local and regional economic development plan; Community development records | Q16: 17191 | R16: 1954 | S16: 693.75 | T16: TRUE | U16: FALSE | V16: TRUE
A17: rag | B17: 2 | C17: 00_sample_project | D17: Leadership | E17: LD3.3 | F17: Conduct a Life-Cycle Assessment | G17: 12 | H17: Applicable | I17: No Level | J17: 0 | K17: 0 | M17: QA:Insufficient Data(No information on life-cycle assessment) | QB:Insufficient Data(No information on environmental impacts or resource usage) | N17: A + B required for Improved | O17: Conduct life-cycle assessment | P17: Life-cycle assessment report; Environmental impact statement | Q17: 17191 | R17: 1954 | S17: 693.75 | T17: TRUE | U17: FALSE | V17: TRUE
A18: rag | B18: 2 | C18: 00_sample_project | D18: Natural World | E18: NW1.1 | F18: Conserve Natural Areas | G18: 14 | H18: APPLICABLE | I18: Improved | J18: 2 | K18: 14.3 | L18: The project is located in Brownsville, PA, and has a site plan, indicating potential natural areas to conserve. | M18: QA:Insufficient Data(No information on natural area conservation) | QB:Insufficient Data(No information on habitat preservation) | N18: A + B required for Improved | O18: Conduct site analysis to identify natural areas; Develop conservation plan | P18: Site analysis report; Conservation plan | Q18: 17916 | R18: 1325 | S18: 506.66 | T18: TRUE | U18: FALSE | V18: TRUE
A19: rag | B19: 2 | C19: 00_sample_project | D19: Natural World | E19: NW1.2 | F19: Provide Wetland and Surface Water Buffers | G19: 10 | H19: APPLICABLE | I19: Improved | J19: 2 | K19: 20 | L19: The project has a site plan, indicating potential wetlands or surface water to buffer. | M19: QA:Insufficient Data(No information on wetland or surface water buffers) | QB:Insufficient Data(No information on buffer zone size) | N19: A + B required for Improved | O19: Conduct site analysis to identify wetlands or surface water; Develop buffer zone plan | P19: Site analysis report; Buffer zone plan | Q19: 17916 | R19: 1325 | S19: 506.66 | T19: TRUE | U19: FALSE | V19: TRUE
A20: rag | B20: 2 | C20: 00_sample_project | D20: Natural World | E20: NW2.2 | F20: Manage Stormwater | G20: 24 | H20: APPLICABLE | I20: Improved | J20: 2 | K20: 8.3 | L20: The project has a site plan, indicating potential stormwater management needs. | M20: QA:Insufficient Data(No information on stormwater management) | QB:Insufficient Data(No information on rate or quantity of runoff) | N20: A + B required for Improved | O20: Conduct stormwater analysis; Develop stormwater management plan | P20: Stormwater analysis report; Stormwater management plan | Q20: 17916 | R20: 1325 | S20: 506.66 | T20: TRUE | U20: FALSE | V20: TRUE
A21: rag | B21: 2 | C21: 00_sample_project | D21: Natural World | E21: NW2.4 | F21: Protect Surface and Groundwater Quality | G21: 14 | H21: APPLICABLE | I21: Improved | J21: 1 | K21: 7.1 | L21: The project has a site plan, indicating potential surface or groundwater quality concerns. | M21: QA:Insufficient Data(No information on surface or groundwater quality protection) | QB:Insufficient Data(No information on pollution prevention measures) | N21: A + B required for Improved | O21: Conduct water quality analysis; Develop pollution prevention plan | P21: Water quality analysis report; Pollution prevention plan | Q21: 17916 | R21: 1325 | S21: 506.66 | T21: TRUE | U21: FALSE | V21: TRUE
A22: rag | B22: 2 | C22: 00_sample_project | D22: Natural World | E22: NW3.3 | F22: Maintain Floodplain Functions | G22: 14 | H22: APPLICABLE | I22: Improved | J22: 1 | K22: 7.1 | L22: The project is located in Brownsville, PA, and has a site plan, indicating potential floodplain functions to maintain. | M22: QA:Insufficient Data(No information on floodplain functions) | QB:Insufficient Data(No information on vegetated zones preservation) | N22: A + B required for Improved | O22: Conduct floodplain analysis; Develop floodplain management plan | P22: Floodplain analysis report; Floodplain management plan | Q22: 17916 | R22: 1325 | S22: 506.66 | T22: TRUE | U22: FALSE | V22: TRUE
A23: rag | B23: 2 | C23: 00_sample_project | D23: Natural World | E23: NW3.5 | F23: Protect Soil Health | G23: 10 | H23: APPLICABLE | I23: Improved | J23: 2 | K23: 20 | L23: The project has a site plan, indicating potential soil health concerns. | M23: QA:Insufficient Data(No information on soil health protection) | QB:Insufficient Data(No information on erosion control measures) | N23: A + B required for Improved | O23: Conduct soil analysis; Develop erosion control plan | P23: Soil analysis report; Erosion control plan | Q23: 17916 | R23: 1325 | S23: 506.66 | T23: TRUE | U23: FALSE | V23: TRUE
A24: rag | B24: 2 | C24: 00_sample_project | D24: Quality Of Life | E24: QL1.1 | F24: Improve Community Quality of Life | G24: 26 | H24: Applicable | I24: Improved | J24: 5 | K24: 19.2 | L24: The project is a mixed-use development with residential, commercial, and community spaces, indicating potential for community quality of life improvements. | M24: QA:Likely Yes(Project includes live/work units and community spaces.) | QB:Insufficient Data(Lack of information on community engagement and feedback mechanisms.) | QC:Likely Yes(Project incorporates green spaces and outdoor areas.) | QD:Insufficient Data(Lack of information on accessibility features and universal design principles.) | N24: A + B | O24: Conduct community outreach and engagement to inform design decisions.; Incorporate accessible and universal design principles into the project. | P24: Community engagement records; Accessibility features and universal design principles documentation | Q24: 17220 | R24: 2964 | S24: 1069.15 | T24: TRUE | U24: FALSE | V24: TRUE
A25: rag | B25: 2 | C25: 00_sample_project | D25: Quality Of Life | E25: QL1.2 | F25: Enhance Public Health & Safety | G25: 20 | H25: Applicable | I25: Improved | J25: 7 | K25: 35 | L25: The project includes residential and commercial spaces, indicating potential public health and safety concerns. | M25: QA:Likely Yes(Project incorporates natural ventilation and daylighting strategies.) | QB:Insufficient Data(Lack of information on indoor air quality monitoring and maintenance protocols.) | QC:Likely Yes(Project includes emergency response plan and fire suppression systems.) | N25: A + B | O25: Develop indoor air quality monitoring and maintenance protocols.; Incorporate public health and safety considerations into the project's emergency response plan. | P25: Indoor air quality monitoring and maintenance protocols; Public health and safety considerations documentation | Q25: 17220 | R25: 2964 | S25: 1069.15 | T25: TRUE | U25: FALSE | V25: TRUE
A26: rag | B26: 2 | C26: 00_sample_project | D26: Quality Of Life | E26: QL1.3 | F26: Improve Construction Safety | G26: 14 | H26: Applicable | I26: Improved | J26: 5 | K26: 35.7 | L26: The project involves construction activities, indicating potential construction safety concerns. | M26: QA:Likely Yes(Project includes construction safety plan and training programs.) | QB:Insufficient Data(Lack of information on site-specific hazard assessments and mitigation strategie) | N26: A + B | O26: Conduct site-specific hazard assessments and develop mitigation strategies.; Incorporate construction safety considerations into the project's overall safety plan. | P26: Construction safety plan and training programs documentation; Site-specific hazard assessments and mitigation strategies documentation | Q26: 17220 | R26: 2964 | S26: 1069.15 | T26: TRUE | U26: FALSE | V26: TRUE
